<?xml version="1.0" encoding="utf-8"?>
<!-- This URDF was automatically created by SolidWorks to URDF Exporter! Originally created by Stephen Brawner (brawner@gmail.com) 
     Commit Version: 1.6.0-1-g15f4949  Build Version: 1.6.7594.29634
     For more information, please see http://wiki.ros.org/sw_urdf_exporter -->
<robot
  name="dual_arm_spacerobot">

  <link
    name="base_link">
    <inertial>
      <origin
        xyz="0 0 0"
        rpy="0 0 0" />
      <mass
        value="5000" />
      <inertia
        ixx="7000"
        ixy="10"
        ixz="300"
        iyy="7000"
        iyz="30"
        izz="7000" />
    </inertial>
    <visual>
      <origin
        xyz="0 0 0"
        rpy="0 0 0" />
      <geometry>
        <mesh
          filename="./jxb_5p5/meshes/base_link.STL" />
      </geometry>
      <material
        name="">
        <color
          rgba="0.529411764705882 0.549019607843137 0.549019607843137 1" />
      </material>
    </visual>
    <collision>
      <origin
        xyz="0 0 0"
        rpy="0 0 0" />
      <geometry>
        <mesh
          filename="./jxb_5p5/meshes/base_link.STL" />
      </geometry>
    </collision>
  </link>

      <joint
    name="fixed_joint_2"
    type="fixed">
<origin
             xyz="1.1800 -0.5024 -1.0020"
             rpy="-2.3562 0.0000 3.1414" />
    <parent
      link="base_link" />
    <child
      link="link2_0" />
    <axis
      xyz="0 0 0" />
  </joint>
  
  <link
    name="link2_0">
    <inertial>
      <origin
        xyz="0 0.0137766948290011 0.0803537131910938"
        rpy="0 0 0" />
      <mass
        value="1.73185647829055" />
      <inertia
        ixx="0.00748851623721393"
        ixy="8.68006091477483E-20"
        ixz="-5.18963998796993E-19"
        iyy="0.00606777002697088"
        iyz="0.000930465605471473"
        izz="0.00347802069147927" />
    </inertial>
    <visual>
      <origin
        xyz="0 0 0"
        rpy="0 0 0" />
      <geometry>
        <mesh
          filename="./jxb_5p5/meshes/link0.STL" />
      </geometry>
      <material
        name="">
        <color
          rgba="0.792156862745098 0.819607843137255 0.933333333333333 1" />
      </material>
    </visual>
    <collision>
      <origin
        xyz="0 0 0"
        rpy="0 0 0" />
      <geometry>
        <mesh
          filename="./jxb_5p5/meshes/link0.STL" />
      </geometry>
    </collision>
  </link>
  <link
    name="link2_1">
    <inertial>
      <origin
        xyz="0.0054612 -9.8658E-08 0.17936"
        rpy="0 0 0" />
      <mass
        value="5.0169" />
      <inertia
        ixx="0.058014"
        ixy="5.3634E-09"
        ixz="-0.0022914"
        iyy="0.059094"
        iyz="1.4754E-08"
        izz="0.012201" />
    </inertial>
    <visual>
      <origin
        xyz="0 0 0"
        rpy="0 0 0" />
      <geometry>
        <mesh
          filename="./jxb_5p5/meshes/link1.STL" />
      </geometry>
      <material
        name="">
        <color
          rgba="0.79216 0.81961 0.93333 1" />
      </material>
    </visual>
    <collision>
      <origin
        xyz="0 0 0"
        rpy="0 0 0" />
      <geometry>
        <mesh
          filename="./jxb_5p5/meshes/link1.STL" />
      </geometry>
    </collision>
  </link>
  <joint
    name="joint2_1"
    type="revolute">
    <origin
      xyz="0 0 0.18605"
      rpy="0 0 0" />
    <parent
      link="link2_0" />
    <child
      link="link2_1" />
    <axis
      xyz="0 0 1" />
    <limit
      lower="-3.14"
      upper="3.14"
      effort="250"
      velocity="0.09" />
  </joint>
  <link
    name="link2_2">
    <inertial>
      <origin
        xyz="-6.17355321308466E-08 -0.0143329703743799 0.144445368888058"
        rpy="0 0 0" />
      <mass
        value="4.93041626027163" />
      <inertia
        ixx="0.0396094585867979"
        ixy="-4.59592948281623E-08"
        ixz="1.26913797145314E-09"
        iyy="0.0352790475757088"
        iyz="0.00309679087652211"
        izz="0.0164853503444288" />
    </inertial>
    <visual>
      <origin
        xyz="0 0 0"
        rpy="0 0 0" />
      <geometry>
        <mesh
          filename="./jxb_5p5/meshes/link2.STL" />
      </geometry>
      <material
        name="">
        <color
          rgba="0.792156862745098 0.819607843137255 0.933333333333333 1" />
      </material>
    </visual>
    <collision>
      <origin
        xyz="0 0 0"
        rpy="0 0 0" />
      <geometry>
        <mesh
          filename="./jxb_5p5/meshes/link2.STL" />
      </geometry>
    </collision>
  </link>
  <joint
    name="joint2_2"
    type="revolute">
    <origin
      xyz="0.081309 0 0.26299"
      rpy="0 1.5708 0" />
    <parent
      link="link2_1" />
    <child
      link="link2_2" />
    <axis
      xyz="0 0 1" />
    <limit
      lower="-3.14"
      upper="3.14"
      effort="250"
      velocity="0.09" />
  </joint>
  <link
    name="link2_3">
    <inertial>
      <origin
        xyz="-1.31363010580365E-07 1.28351409245202 0.109942319550625"
        rpy="0 0 0" />
      <mass
        value="51.295197481648" />
      <inertia
        ixx="37.1233178065453"
        ixy="2.48008824830899E-06"
        ixz="-2.80753217402778E-06"
        iyy="0.169241619258337"
        iyz="-0.214904575766479"
        izz="37.1108697570616" />
    </inertial>
    <visual>
      <origin
        xyz="0 0 0"
        rpy="0 0 0" />
      <geometry>
        <mesh
          filename="./jxb_5p5/meshes/link3.STL" />
      </geometry>
      <material
        name="">
        <color
          rgba="0.792156862745098 0.819607843137255 0.933333333333333 1" />
      </material>
    </visual>
    <collision>
      <origin
        xyz="0 0 0"
        rpy="0 0 0" />
      <geometry>
        <mesh
          filename="./jxb_5p5/meshes/link3.STL" />
      </geometry>
    </collision>
  </link>
  <joint
    name="joint2_3"
    type="revolute">
    <origin
      xyz="0 -0.11352 0.18827"
      rpy="1.5708 0 0" />
    <parent
      link="link2_2" />
    <child
      link="link2_3" />
    <axis
      xyz="0 0 1" />
    <limit
      lower="-3.14"
      upper="3.14"
      effort="250"
      velocity="0.09" />
  </joint>
  <link
    name="link2_4">
    <inertial>
      <origin
        xyz="1.3136E-07 -1.289 0.1089"
        rpy="0 0 0" />
      <mass
        value="51.295" />
      <inertia
        ixx="37.123"
        ixy="-2.4801E-06"
        ixz="-2.8075E-06"
        iyy="0.16924"
        iyz="0.2149"
        izz="37.111" />
    </inertial>
    <visual>
      <origin
        xyz="0 0 0"
        rpy="0 0 0" />
      <geometry>
        <mesh
          filename="./jxb_5p5/meshes/link4.STL" />
      </geometry>
      <material
        name="">
        <color
          rgba="0.79216 0.81961 0.93333 1" />
      </material>
    </visual>
    <collision>
      <origin
        xyz="0 0 0"
        rpy="0 0 0" />
      <geometry>
        <mesh
          filename="./jxb_5p5/meshes/link4.STL" />
      </geometry>
    </collision>
  </link>
  <joint
    name="joint2_4"
    type="revolute">
    <origin
      xyz="0 2.5725 0.21885"
      rpy="0 0 0" />
    <parent
      link="link2_3" />
    <child
      link="link2_4" />
    <axis
      xyz="0 0 1" />
    <limit
      lower="-3.14"
      upper="3.14"
      effort="250"
      velocity="0.09" />
  </joint>
  <link
    name="link2_5">
    <inertial>
      <origin
        xyz="6.173553229738E-08 -0.0438218186119419 0.0991900765006201"
        rpy="0 0 0" />
      <mass
        value="4.93041626027163" />
      <inertia
        ixx="0.0396094585867979"
        ixy="-1.26913797211671E-09"
        ixz="4.59592948288677E-08"
        iyy="0.0164853503444288"
        iyz="0.00309679087652211"
        izz="0.0352790475757088" />
    </inertial>
    <visual>
      <origin
        xyz="0 0 0"
        rpy="0 0 0" />
      <geometry>
        <mesh
          filename="./jxb_5p5/meshes/link5.STL" />
      </geometry>
      <material
        name="">
        <color
          rgba="0.792156862745098 0.819607843137255 0.933333333333333 1" />
      </material>
    </visual>
    <collision>
      <origin
        xyz="0 0 0"
        rpy="0 0 0" />
      <geometry>
        <mesh
          filename="./jxb_5p5/meshes/link5.STL" />
      </geometry>
    </collision>
  </link>
  <joint
    name="joint2_5"
    type="revolute">
    <origin
      xyz="0 -2.5725 0.21884625"
      rpy="0 0 0" />
    <parent
      link="link2_4" />
    <child
      link="link2_5" />
    <axis
      xyz="0 0 1" />
    <limit
      lower="-3.14"
      upper="3.14"
      effort="250"
      velocity="0.09" />
  </joint>
  <link
    name="link2_6">
    <inertial>
      <origin
        xyz="0.0836298735887332 9.86580771522583E-08 0.0758481549778378"
        rpy="0 0 0" />
      <mass
        value="5.01691901206329" />
      <inertia
        ixx="0.01220066391638"
        ixy="1.47536226472268E-08"
        ixz="-0.00229135765937923"
        iyy="0.0590937930128955"
        iyz="5.36338185932921E-09"
        izz="0.0580136051663553" />
    </inertial>
    <visual>
      <origin
        xyz="0 0 0"
        rpy="0 0 0" />
      <geometry>
        <mesh
          filename="./jxb_5p5/meshes/link6.STL" />
      </geometry>
      <material
        name="">
        <color
          rgba="0.792156862745098 0.819607843137255 0.933333333333333 1" />
      </material>
    </visual>
    <collision>
      <origin
        xyz="0 0 0"
        rpy="0 0 0" />
      <geometry>
        <mesh
          filename="./jxb_5p5/meshes/link6.STL" />
      </geometry>
    </collision>
  </link>
  <joint
    name="joint2_6"
    type="revolute">
    <origin
      xyz="0 -0.18827 0.11352"
      rpy="1.5708 0 0" />
    <parent
      link="link2_5" />
    <child
      link="link2_6" />
    <axis
      xyz="0 0 1" />
    <limit
      lower="-3.14"
      upper="3.14"
      effort="250"
      velocity="0.09" />
  </joint>
  <link
    name="link2_7">
    <inertial>
      <origin
        xyz="-6.93889390390723E-18 -0.0137766948290011 0.105693161808906"
        rpy="0 0 0" />
      <mass
        value="1.73185647829055" />
      <inertia
        ixx="0.00748851623721393"
        ixy="-9.55719666872922E-20"
        ixz="4.82830895364232E-19"
        iyy="0.00606777002697088"
        iyz="0.000930465605471473"
        izz="0.00347802069147927" />
    </inertial>
    <visual>
      <origin
        xyz="0 0 0"
        rpy="0 0 0" />
      <geometry>
        <mesh
          filename="./jxb_5p5/meshes/link7.STL" />
      </geometry>
      <material
        name="">
        <color
          rgba="0.792156862745098 0.819607843137255 0.933333333333333 1" />
      </material>
    </visual>
    <collision>
      <origin
        xyz="0 0 0"
        rpy="0 0 0" />
      <geometry>
        <mesh
          filename="./jxb_5p5/meshes/link7.STL" />
      </geometry>
    </collision>
  </link>
  <joint
    name="joint2_7"
    type="revolute">
    <origin
      xyz="0.26299 0 0.081309"
      rpy="0 1.5708 0" />
    <parent
      link="link2_6" />
    <child
      link="link2_7" />
    <axis
      xyz="0 0 1" />
    <limit
      lower="-3.14"
      upper="3.14"
      effort="250"
      velocity="0.09" />
  </joint>
</robot>
